Workbook

Sheet Resumen
A1: Inventario de fuentes de eventos culturales de Chile
A2: Inventario y estado de integración revisados al 31 de octubre de 2026. Las auditorías técnicas conservan su fecha original.
A4: Indicador | B4: Valor | D4: Indicador | E4: Valor | F4: Integración actual | G4: Valor
A5: Registros del inventario | B5: =COUNTA(Fuentes!$A$2:$A$396) -> 395 | D5: Revisión manual | E5: =COUNTIF(Fuentes!$R$2:$R$396,"Revisión manual") -> 38 | F5: Configuradas y habilitadas | G5: =COUNTIFS(Fuentes!$L$2:$L$396,"Integrada configurada") -> 29
A6: Fuentes digitales elegibles | B6: =COUNTIFS(Fuentes!$M$2:$M$396,"Sí") -> 105 | D6: No aprobadas | E6: =COUNTIF(Fuentes!$R$2:$R$396,"No aprobada") -> 5 | F6: Con aporte publicado | G6: =COUNTIFS(Fuentes!$L$2:$L$396,"Integrada configurada",Fuentes!$AA$2:$AA$396,"Con aporte publicado") -> 23
A7: Con aprobación técnica registrada | B7: =COUNTIF(Fuentes!$R$2:$R$396,"Aprobada técnicamente") -> 65 | D7: Referencias sin agenda | E7: =COUNTIF(Fuentes!$R$2:$R$396,"Referencia sin agenda") -> 287 | F7: Integradas / digitales elegibles | G7: =IF(B6=0,0,G5/B6) -> 0.27619048
A8: Aprobación técnica registrada (%) | B8: =IF(B6=0,0,B7/B6) -> 0.61904762 | D8: Regiones representadas | E8: =COUNTIF(B14:B29,">0") -> 16 | F8: Con aporte / habilitadas del mes | G8: =IF(G9=0,0,G6/G9) -> 0.82142857
A9: Publicados en Supabase al corte | B9: =SUM(Fuentes!$Z$2:$Z$396) -> 2546 | D9: Estacionales fuera de mes | E9: =COUNTIFS(Fuentes!$AA$2:$AA$396,"Estacional fuera de mes") -> 1 | F9: Habilitadas en el mes del corte | G9: =G5-E9 -> 28
A11: Región / alcance | B11: Total | C11: Digital elegible | D11: Aprobada técnicamente | F11: Decisión de validación | G11: Cantidad
A12: Todas | B12: =COUNTIF(Fuentes!$F$2:$F$396,A12) -> 17 | C12: =COUNTIFS(Fuentes!$F$2:$F$396,A12,Fuentes!$M$2:$M$396,"Sí") -> 17 | D12: =COUNTIFS(Fuentes!$F$2:$F$396,A12,Fuentes!$R$2:$R$396,"Aprobada técnicamente") -> 8 | F12: Aprobada técnicamente | G12: =COUNTIF(Fuentes!$R$2:$R$396,F12) -> 65
A13: Varias | B13: =COUNTIF(Fuentes!$F$2:$F$396,A13) -> 6 | C13: =COUNTIFS(Fuentes!$F$2:$F$396,A13,Fuentes!$M$2:$M$396,"Sí") -> 6 | D13: =COUNTIFS(Fuentes!$F$2:$F$396,A13,Fuentes!$R$2:$R$396,"Aprobada técnicamente") -> 5 | F13: Revisión manual | G13: =COUNTIF(Fuentes!$R$2:$R$396,F13) -> 38
A14: Región de Arica y Parinacota | B14: =COUNTIF(Fuentes!$F$2:$F$396,A14) -> 16 | C14: =COUNTIFS(Fuentes!$F$2:$F$396,A14,Fuentes!$M$2:$M$396,"Sí") -> 2 | D14: =COUNTIFS(Fuentes!$F$2:$F$396,A14,Fuentes!$R$2:$R$396,"Aprobada técnicamente") -> 1 | F14: No aprobada | G14: =COUNTIF(Fuentes!$R$2:$R$396,F14) -> 5
A15: Región de Tarapacá | B15: =COUNTIF(Fuentes!$F$2:$F$396,A15) -> 16 | C15: =COUNTIFS(Fuentes!$F$2:$F$396,A15,Fuentes!$M$2:$M$396,"Sí") -> 3 | D15: =COUNTIFS(Fuentes!$F$2:$F$396,A15,Fuentes!$R$2:$R$396,"Aprobada técnicamente") -> 1 | F15: Referencia sin agenda | G15: =COUNTIF(Fuentes!$R$2:$R$396,F15) -> 287
A16: Región de Antofagasta | B16: =COUNTIF(Fuentes!$F$2:$F$396,A16) -> 11 | C16: =COUNTIFS(Fuentes!$F$2:$F$396,A16,Fuentes!$M$2:$M$396,"Sí") -> 3 | D16: =COUNTIFS(Fuentes!$F$2:$F$396,A16,Fuentes!$R$2:$R$396,"Aprobada técnicamente") -> 3
A17: Región de Atacama | B17: =COUNTIF(Fuentes!$F$2:$F$396,A17) -> 11 | C17: =COUNTIFS(Fuentes!$F$2:$F$396,A17,Fuentes!$M$2:$M$396,"Sí") -> 2 | D17: =COUNTIFS(Fuentes!$F$2:$F$396,A17,Fuentes!$R$2:$R$396,"Aprobada técnicamente") -> 2
A18: Región de Coquimbo | B18: =COUNTIF(Fuentes!$F$2:$F$396,A18) -> 21 | C18: =COUNTIFS(Fuentes!$F$2:$F$396,A18,Fuentes!$M$2:$M$396,"Sí") -> 4 | D18: =COUNTIFS(Fuentes!$F$2:$F$396,A18,Fuentes!$R$2:$R$396,"Aprobada técnicamente") -> 1 | F18: Cómo interpretar la decisión | G18: Cómo interpretar la decisión | H18: Cómo interpretar la decisión
A19: Región de Valparaíso | B19: =COUNTIF(Fuentes!$F$2:$F$396,A19) -> 39 | C19: =COUNTIFS(Fuentes!$F$2:$F$396,A19,Fuentes!$M$2:$M$396,"Sí") -> 8 | D19: =COUNTIFS(Fuentes!$F$2:$F$396,A19,Fuentes!$R$2:$R$396,"Aprobada técnicamente") -> 7 | F19: La aprobación técnica no es una licencia legal. Las integraciones actuales se cuentan por configuración habilitada; el aporte se comprueba con registros publicados no suprimidos. Una fuente sin aporte no se considera fallida sin revisar su ejecución. | G19: Aprobada técnicamente significa que la fuente cumple las reglas automáticas de acceso, relevancia cultural, cobertura chilena y señales de agenda. No equivale a una licencia legal de reutilización. Antes de integrarla de forma permanente deben revisarse sus términos de uso. Revisión manual agrupa páginas dinámicas, bloqueadas o con evidencia insuficiente. | H19: Aprobada técnicamente significa que la fuente cumple las reglas automáticas de acceso, relevancia cultural, cobertura chilena y señales de agenda. No equivale a una licencia legal de reutilización. Antes de integrarla de forma permanente deben revisarse sus términos de uso. Revisión manual agrupa páginas dinámicas, bloqueadas o con evidencia insuficiente.
A20: Región Metropolitana de Santiago | B20: =COUNTIF(Fuentes!$F$2:$F$396,A20) -> 41 | C20: =COUNTIFS(Fuentes!$F$2:$F$396,A20,Fuentes!$M$2:$M$396,"Sí") -> 26 | D20: =COUNTIFS(Fuentes!$F$2:$F$396,A20,Fuentes!$R$2:$R$396,"Aprobada técnicamente") -> 19 | F20: Aprobada técnicamente significa que la fuente cumple las reglas automáticas de acceso, relevancia cultural, cobertura chilena y señales de agenda. No equivale a una licencia legal de reutilización. Antes de integrarla de forma permanente deben revisarse sus términos de uso. Revisión manual agrupa páginas dinámicas, bloqueadas o con evidencia insuficiente. | G20: Aprobada técnicamente significa que la fuente cumple las reglas automáticas de acceso, relevancia cultural, cobertura chilena y señales de agenda. No equivale a una licencia legal de reutilización. Antes de integrarla de forma permanente deben revisarse sus términos de uso. Revisión manual agrupa páginas dinámicas, bloqueadas o con evidencia insuficiente. | H20: Aprobada técnicamente significa que la fuente cumple las reglas automáticas de acceso, relevancia cultural, cobertura chilena y señales de agenda. No equivale a una licencia legal de reutilización. Antes de integrarla de forma permanente deben revisarse sus términos de uso. Revisión manual agrupa páginas dinámicas, bloqueadas o con evidencia insuficiente.
A21: Región del Libertador General Bernardo O'Higgins | B21: =COUNTIF(Fuentes!$F$2:$F$396,A21) -> 25 | C21: =COUNTIFS(Fuentes!$F$2:$F$396,A21,Fuentes!$M$2:$M$396,"Sí") -> 3 | D21: =COUNTIFS(Fuentes!$F$2:$F$396,A21,Fuentes!$R$2:$R$396,"Aprobada técnicamente") -> 2 | F21: Aprobada técnicamente significa que la fuente cumple las reglas automáticas de acceso, relevancia cultural, cobertura chilena y señales de agenda. No equivale a una licencia legal de reutilización. Antes de integrarla de forma permanente deben revisarse sus términos de uso. Revisión manual agrupa páginas dinámicas, bloqueadas o con evidencia insuficiente. | G21: Aprobada técnicamente significa que la fuente cumple las reglas automáticas de acceso, relevancia cultural, cobertura chilena y señales de agenda. No equivale a una licencia legal de reutilización. Antes de integrarla de forma permanente deben revisarse sus términos de uso. Revisión manual agrupa páginas dinámicas, bloqueadas o con evidencia insuficiente. | H21: Aprobada técnicamente significa que la fuente cumple las reglas automáticas de acceso, relevancia cultural, cobertura chilena y señales de agenda. No equivale a una licencia legal de reutilización. Antes de integrarla de forma permanente deben revisarse sus términos de uso. Revisión manual agrupa páginas dinámicas, bloqueadas o con evidencia insuficiente.
A22: Región del Maule | B22: =COUNTIF(Fuentes!$F$2:$F$396,A22) -> 60 | C22: =COUNTIFS(Fuentes!$F$2:$F$396,A22,Fuentes!$M$2:$M$396,"Sí") -> 3 | D22: =COUNTIFS(Fuentes!$F$2:$F$396,A22,Fuentes!$R$2:$R$396,"Aprobada técnicamente") -> 2 | F22: Aprobada técnicamente significa que la fuente cumple las reglas automáticas de acceso, relevancia cultural, cobertura chilena y señales de agenda. No equivale a una licencia legal de reutilización. Antes de integrarla de forma permanente deben revisarse sus términos de uso. Revisión manual agrupa páginas dinámicas, bloqueadas o con evidencia insuficiente. | G22: Aprobada técnicamente significa que la fuente cumple las reglas automáticas de acceso, relevancia cultural, cobertura chilena y señales de agenda. No equivale a una licencia legal de reutilización. Antes de integrarla de forma permanente deben revisarse sus términos de uso. Revisión manual agrupa páginas dinámicas, bloqueadas o con evidencia insuficiente. | H22: Aprobada técnicamente significa que la fuente cumple las reglas automáticas de acceso, relevancia cultural, cobertura chilena y señales de agenda. No equivale a una licencia legal de reutilización. Antes de integrarla de forma permanente deben revisarse sus términos de uso. Revisión manual agrupa páginas dinámicas, bloqueadas o con evidencia insuficiente.
A23: Región de Ñuble | B23: =COUNTIF(Fuentes!$F$2:$F$396,A23) -> 16 | C23: =COUNTIFS(Fuentes!$F$2:$F$396,A23,Fuentes!$M$2:$M$396,"Sí") -> 2 | D23: =COUNTIFS(Fuentes!$F$2:$F$396,A23,Fuentes!$R$2:$R$396,"Aprobada técnicamente") -> 1 | F23: Aprobada técnicamente significa que la fuente cumple las reglas automáticas de acceso, relevancia cultural, cobertura chilena y señales de agenda. No equivale a una licencia legal de reutilización. Antes de integrarla de forma permanente deben revisarse sus términos de uso. Revisión manual agrupa páginas dinámicas, bloqueadas o con evidencia insuficiente. | G23: Aprobada técnicamente significa que la fuente cumple las reglas automáticas de acceso, relevancia cultural, cobertura chilena y señales de agenda. No equivale a una licencia legal de reutilización. Antes de integrarla de forma permanente deben revisarse sus términos de uso. Revisión manual agrupa páginas dinámicas, bloqueadas o con evidencia insuficiente. | H23: Aprobada técnicamente significa que la fuente cumple las reglas automáticas de acceso, relevancia cultural, cobertura chilena y señales de agenda. No equivale a una licencia legal de reutilización. Antes de integrarla de forma permanente deben revisarse sus términos de uso. Revisión manual agrupa páginas dinámicas, bloqueadas o con evidencia insuficiente.
A24: Región del Biobío | B24: =COUNTIF(Fuentes!$F$2:$F$396,A24) -> 34 | C24: =COUNTIFS(Fuentes!$F$2:$F$396,A24,Fuentes!$M$2:$M$396,"Sí") -> 7 | D24: =COUNTIFS(Fuentes!$F$2:$F$396,A24,Fuentes!$R$2:$R$396,"Aprobada técnicamente") -> 5
A25: Región de La Araucanía | B25: =COUNTIF(Fuentes!$F$2:$F$396,A25) -> 27 | C25: =COUNTIFS(Fuentes!$F$2:$F$396,A25,Fuentes!$M$2:$M$396,"Sí") -> 3 | D25: =COUNTIFS(Fuentes!$F$2:$F$396,A25,Fuentes!$R$2:$R$396,"Aprobada técnicamente") -> 2
A26: Región de Los Ríos | B26: =COUNTIF(Fuentes!$F$2:$F$396,A26) -> 11 | C26: =COUNTIFS(Fuentes!$F$2:$F$396,A26,Fuentes!$M$2:$M$396,"Sí") -> 4 | D26: =COUNTIFS(Fuentes!$F$2:$F$396,A26,Fuentes!$R$2:$R$396,"Aprobada técnicamente") -> 2
A27: Región de Los Lagos | B27: =COUNTIF(Fuentes!$F$2:$F$396,A27) -> 23 | C27: =COUNTIFS(Fuentes!$F$2:$F$396,A27,Fuentes!$M$2:$M$396,"Sí") -> 5 | D27: =COUNTIFS(Fuentes!$F$2:$F$396,A27,Fuentes!$R$2:$R$396,"Aprobada técnicamente") -> 1
A28: Región de Aysén del General Carlos Ibáñez del Campo | B28: =COUNTIF(Fuentes!$F$2:$F$396,A28) -> 6 | C28: =COUNTIFS(Fuentes!$F$2:$F$396,A28,Fuentes!$M$2:$M$396,"Sí") -> 3 | D28: =COUNTIFS(Fuentes!$F$2:$F$396,A28,Fuentes!$R$2:$R$396,"Aprobada técnicamente") -> 2
A29: Región de Magallanes y de la Antártica Chilena | B29: =COUNTIF(Fuentes!$F$2:$F$396,A29) -> 13 | C29: =COUNTIFS(Fuentes!$F$2:$F$396,A29,Fuentes!$M$2:$M$396,"Sí") -> 3 | D29: =COUNTIFS(Fuentes!$F$2:$F$396,A29,Fuentes!$R$2:$R$396,"Aprobada técnicamente") -> 0
A31: Eventos de última ingesta | B31: 2491 | D31: Fecha de última ingesta (Chile) | E31: 46325.264
A32: Los publicados al corte no equivalen necesariamente a eventos vigentes hoy. La ingesta y el catálogo son conteos distintos. Puntajes técnicos históricos: consultar fecha de auditoría.

Sheet Fuentes
A1: ID | B1: Fuente | C1: Institución responsable | D1: Tipo de fuente | E1: Cobertura | F1: Región | G1: Comuna | H1: Áreas culturales | I1: Canal de publicación | J1: URL de eventos | K1: URL de respaldo / evidencia | L1: Estado de integración | M1: Elegible para porcentaje | N1: Prioridad | O1: Método potencial | P1: Verificada el | Q1: Observaciones | R1: Decisión para integración | S1: Puntaje técnico | T1: Confianza | U1: Estado HTTP | V1: robots.txt | W1: URL final validada | X1: Auditada el | Y1: Motivo principal | Z1: Publicados al corte | AA1: Estado operativo al corte | AB1: Evidencia de integración
A2: CL-FUE-0001 | B2: Agenda Universidad de Talca | C2: Universidad de Talca | D2: Fuente configurada en el prototipo | E2: Según fuente | F2: Región del Maule | G2: Talca | H2: Cultura | I2: Conector del prototipo | J2: https://agenda.utalca.cl/ | K2: https://agenda.utalca.cl/ | L2: Integrada configurada | M2: Sí | N2: Alta | O2: html_cards | P2: 46326 | Q2: Revisión de integración 31-10-2026: configuración habilitada; 8 registros publicados no suprimidos en Supabase. Con aporte publicado. Los puntajes y la auditoría técnica anteriores no se recalcularon. Antecedente: Ejecución reciente: conector funcional. | R2: Aprobada técnicamente | S2: 93 | T2: alta | U2: 200 | V2: Permite | W2: https://agenda.utalca.cl/ | X2: 46279.625 | Y2: Operativa: agenda accesible y con señales de eventos. | Z2: 8 | AA2: Con aporte publicado | AB2: https://github.com/sunsitox/sunsitox-Scraper_de_eventos_culturales/actions/runs/41029844675
A3: CL-FUE-0002 | B3: Centro Cultural La Moneda | C3: Centro Cultural La Moneda | D3: Fuente configurada en el prototipo | E3: Según fuente | F3: Región Metropolitana de Santiago | G3: Santiago | H3: Cultura | I3: Conector del prototipo | J3: https://www.cclm.cl/actividades-y-talleres/ | K3: https://www.cclm.cl/actividades-y-talleres/ | L3: Integrada configurada | M3: Sí | N3: Alta | O3: html_cards | P3: 46326 | Q3: Revisión de integración 31-10-2026: configuración habilitada; 4 registros publicados no suprimidos en Supabase. Con aporte publicado. Los puntajes y la auditoría técnica anteriores no se recalcularon. Antecedente: Ejecución reciente: conector funcional. | R3: Aprobada técnicamente | S3: 99 | T3: alta | U3: 200 | V3: Permite | W3: https://www.cclm.cl/actividades-y-talleres/ | X3: 46279.625 | Y3: Operativa: agenda accesible y con señales de eventos. | Z3: 4 | AA3: Con aporte publicado | AB3: https://github.com/sunsitox/sunsitox-Scraper_de_eventos_culturales/actions/runs/41029844675
A4: CL-FUE-0003 | B4: Chile Cultura | C4: Chile Cultura | D4: Fuente configurada en el prototipo | E4: Nacional | F4: Todas | H4: Multidisciplinario | I4: Conector del prototipo | J4: https://chilecultura.gob.cl/ | K4: https://chilecultura.gob.cl/ | L4: Integrada configurada | M4: Sí | N4: Alta | O4: chilecultura_api | P4: 46326 | Q4: Revisión de integración 31-10-2026: configuración habilitada; 289 registros publicados no suprimidos en Supabase. Con aporte publicado. Los puntajes y la auditoría técnica anteriores no se recalcularon. Antecedente: Ejecución reciente: API nacional funcional. | R4: Aprobada técnicamente | S4: 86 | T4: alta | U4: 200 | V4: Sin dato | W4: https://chilecultura.gob.cl/ | X4: 46279.625 | Y4: Operativa: API nacional con cobertura regional. | Z4: 289 | AA4: Con aporte publicado | AB4: https://github.com/sunsitox/sunsitox-Scraper_de_eventos_culturales/actions/runs/41029844675
A5: CL-FUE-0004 | B5: Espacio Cultural Viña del Mar | C5: Corporación Cultural de Viña del Mar | D5: Fuente configurada en el prototipo | E5: Según fuente | F5: Región de Valparaíso | G5: Viña del Mar | H5: Multidisciplinario | I5: Conector del prototipo | J5: https://www.culturaviva.cl/actividades/ | K5: https://www.culturaviva.cl/actividades/ | L5: Integrada configurada | M5: Sí | N5: Alta | O5: tribe_events_api | P5: 46326 | Q5: Revisión de integración 31-10-2026: configuración habilitada; 0 registros publicados no suprimidos en Supabase. Sin aporte publicado. Los puntajes y la auditoría técnica anteriores no se recalcularon. Antecedente: API operativa; al corte no publica eventos futuros. | R5: Aprobada técnicamente | S5: 97 | T5: alta | U5: 200 | V5: Permite | W5: https://www.culturaviva.cl/actividades/ | X5: 46279.625 | Y5: La fuente no falló: no tenía eventos vigentes en la respuesta de la API. | Z5: 0 | AA5: Sin aporte publicado | AB5: https://github.com/sunsitox/sunsitox-Scraper_de_eventos_culturales/blob/main/docs/SOURCES.md
A6: CL-FUE-0005 | B6: Enoturismo Chile · Agenda | C6: Enoturismo Chile | D6: Fuente configurada en el prototipo | E6: Según fuente | F6: Todas | H6: Vino; Enoturismo | I6: Conector del prototipo | J6: https://www.enoturismochile.cl/agenda/ | K6: https://www.enoturismochile.cl/agenda/ | L6: Integrada configurada | M6: Sí | N6: Alta | O6: eventon_wordpress | P6: 46326 | Q6: Revisión de integración 31-10-2026: configuración habilitada; 10 registros publicados no suprimidos en Supabase. Con aporte publicado. Los puntajes y la auditoría técnica anteriores no se recalcularon. Antecedente: Conector funcional; se mantiene revisión por la evidencia pública de la agenda. | R6: Revisión manual | S6: 72 | T6: alta | U6: 200 | V6: Permite | W6: https://www.enoturismochile.cl/agenda/ | X6: 46279.625 | Y6: Operativa; requiere revisión de términos y calidad de agenda antes de ampliar alcance. | Z6: 10 | AA6: Con aporte publicado | AB6: https://github.com/sunsitox/sunsitox-Scraper_de_eventos_culturales/actions/runs/41029844675
A7: CL-FUE-0006 | B7: Espacio Riesco · Calendario | C7: Espacio Riesco | D7: Fuente configurada en el prototipo | E7: Según fuente | F7: Región Metropolitana de Santiago | G7: Huechuraba | H7: Evento | I7: Conector del prototipo | J7: https://www.espacioriesco.cl/calendario/ | K7: https://www.espacioriesco.cl/calendario/ | L7: Integrada configurada | M7: Sí | N7: Alta | O7: html_cards | P7: 46326 | Q7: Revisión de integración 31-10-2026: configuración habilitada; 0 registros publicados no suprimidos en Supabase. Sin aporte publicado. Los puntajes y la auditoría técnica anteriores no se recalcularon. Antecedente: Conector funcional; se mantiene revisión por naturaleza generalista de la agenda. | R7: Revisión manual | S7: 79 | T7: alta | U7: 200 | V7: Permite | W7: https://www.espacioriesco.cl/calendario/ | X7: 46279.625 | Y7: Operativa; se filtra por evento según criterio cultural global. | Z7: 0 | AA7: Sin aporte publicado | AB7: https://github.com/sunsitox/sunsitox-Scraper_de_eventos_culturales/blob/main/docs/SOURCES.md
A8: CL-FUE-0007 | B8: FISA · Ferias y Exposiciones | C8: FISA · GL events Chile | D8: Fuente configurada en el prototipo | E8: Según fuente | F8: Todas | H8: Exposición; Feria; Negocios | I8: Conector del prototipo | J8: https://www.fisa.cl/nuestras-ferias/ | K8: https://www.fisa.cl/nuestras-ferias/ | L8: Integrada configurada | M8: Sí | N8: Alta | O8: fisa_portfolio | P8: 46326 | Q8: Revisión de integración 31-10-2026: configuración habilitada; 0 registros publicados no suprimidos en Supabase. Sin aporte publicado. Los puntajes y la auditoría técnica anteriores no se recalcularon. Antecedente: Conector funcional; se mantiene filtro cultural por evento. | R8: Revisión manual | S8: 64 | T8: alta | U8: 200 | V8: Permite | W8: https://www.fisa.cl/nuestras-ferias/ | X8: 46279.625 | Y8: Operativa; incluye solo ferias o exposiciones con componente cultural sustantivo. | Z8: 0 | AA8: Sin aporte publicado | AB8: https://github.com/sunsitox/sunsitox-Scraper_de_eventos_culturales/blob/main/docs/SOURCES.md
A9: CL-FUE-0008 | B9: Centro Cultural GAM | C9: Centro Cultural Gabriela Mistral | D9: Fuente configurada en el prototipo | E9: Según fuente | F9: Región Metropolitana de Santiago | G9: Santiago | H9: Cultura | I9: Conector del prototipo | J9: https://gam.cl/es/calendario/ | K9: https://gam.cl/es/calendario/ | L9: Integrada configurada | M9: Sí | N9: Alta | O9: generic | P9: 46326 | Q9: Revisión de integración 31-10-2026: configuración habilitada; 36 registros publicados no suprimidos en Supabase. Con aporte publicado. Los puntajes y la auditoría técnica anteriores no se recalcularon. Antecedente: Ejecución reciente: conector funcional. | R9: Aprobada técnicamente | S9: 99 | T9: alta | U9: 200 | V9: Permite | W9: https://gam.cl/es/calendario/ | X9: 46279.625 | Y9: Operativa: agenda accesible y con señales de eventos. | Z9: 36 | AA9: Con aporte publicado | AB9: https://github.com/sunsitox/sunsitox-Scraper_de_eventos_culturales/actions/runs/41029844675
A10: CL-FUE-0009 | B10: Maipú en Común | C10: Municipalidad de Maipú | D10: Fuente configurada en el prototipo | E10: Según fuente | F10: Región Metropolitana de Santiago | G10: Maipú | H10: Multidisciplinario | I10: Conector del prototipo | J10: https://www.maipuencomun.cl/ | K10: https://www.maipuencomun.cl/ | L10: Integrada configurada | M10: Sí | N10: Alta | O10: maipu_browser | P10: 46326 | Q10: Revisión de integración 31-10-2026: configuración habilitada; 66 registros publicados no suprimidos en Supabase. Con aporte publicado. Los puntajes y la auditoría técnica anteriores no se recalcularon. Antecedente: Conector de navegador funcional; requiere Playwright instalado. | R10: Revisión manual | S10: 45 | T10: alta | U10: 200 | V10: Sin dato | W10: https://www.maipuencomun.cl/ | X10: 46279.625 | Y10: Operativa; depende del backend municipal y de Playwright. | Z10: 66 | AA10: Con aporte publicado | AB10: https://github.com/sunsitox/sunsitox-Scraper_de_eventos_culturales/actions/runs/41029844675
A11: CL-FUE-0010 | B11: Rancagua Cultura | C11: Corporación de la Cultura y las Artes de Rancagua | D11: Fuente configurada en el prototipo | E11: Según fuente | F11: Región del Libertador Bernardo O'Higgins | G11: Rancagua | H11: Cultura | I11: Conector del prototipo | J11: https://rancaguacultura.cl/event-directory/ | K11: https://rancaguacultura.cl/event-directory/ | L11: Retirada por bloqueo | M11: No | N11: Alta | O11: generic | P11: 46270.667 | Q11: Retirada del scraper por HTTP 403 desde GitHub Actions; no se vuelve a consultar. Los puntajes anteriores, si existen, son históricos. Corregida el 14-09-2026: se ignoran enlaces webcal:// no compatibles con Requests. | R11: No aprobada | S11: 100 | T11: alta | U11: 200 | V11: Permite | W11: https://rancaguacultura.cl/event-directory/ | X11: 46279.625 | Y11: Operativa tras la corrección; el calendario webcal ya no interrumpe la extracción de fichas HTML. | Z11: 0 | AA11: Retirada | AB11: https://github.com/sunsitox/sunsitox-Scraper_de_eventos_culturales/blob/main/docs/SOURCES.md#fuentes-retiradas
A12: CL-FUE-0011 | B12: Santiago Cultura | C12: Subdirección de Cultura · Municipalidad de Santiago | D12: Fuente configurada en el prototipo | E12: Según fuente | F12: Región Metropolitana de Santiago | G12: Santiago | H12: Cultura | I12: Conector del prototipo | J12: https://www.santiagocultura.cl/agenda-cultural/ | K12: https://www.santiagocultura.cl/agenda-cultural/ | L12: Integrada configurada | M12: Sí | N12: Alta | O12: santiago_wordpress | P12: 46326 | Q12: Revisión de integración 31-10-2026: configuración habilitada; 2 registros publicados no suprimidos en Supabase. Con aporte publicado. Los puntajes y la auditoría técnica anteriores no se recalcularon. Antecedente: Conector incremental activo: reutiliza fichas sin cambios y conserva checkpoints. | R12: Aprobada técnicamente | S12: 79 | T12: alta | U12: 200 | V12: Permite | W12: https://www.santiagocultura.cl/agenda-cultural/ | X12: 46285.625 | Y12: Operativa mediante extracción incremental; las fichas históricas sin cambios no se descargan nuevamente. | Z12: 2 | AA12: Con aporte publicado | AB12: https://github.com/sunsitox/sunsitox-Scraper_de_eventos_culturales/actions/runs/41029844675
A13: CL-FUE-0012 | B13: Teatro Municipal de Viña del Mar | C13: Teatro Municipal de Viña del Mar | D13: Fuente configurada en el prototipo | E13: Según fuente | F13: Región de Valparaíso | G13: Viña del Mar | H13: Artes escénicas | I13: Conector del prototipo | J13: https://teatrovina.cl/cartelera/ | K13: https://teatrovina.cl/cartelera/ | L13: Integrada configurada | M13: Sí | N13: Alta | O13: generic | P13: 46326 | Q13: Revisión de integración 31-10-2026: configuración habilitada; 0 registros publicados no suprimidos en Supabase. Sin aporte publicado. Los puntajes y la auditoría técnica anteriores no se recalcularon. Antecedente: Ejecución reciente: conector funcional. | R13: Aprobada técnicamente | S13: 100 | T13: alta | U13: 200 | V13: Permite | W13: https://teatrovina.cl/cartelera/ | X13: 46279.625 | Y13: Operativa: cartelera accesible y con señales de eventos. | Z13: 0 | AA13: Sin aporte publicado | AB13: https://github.com/sunsitox/sunsitox-Scraper_de_eventos_culturales/blob/main/docs/SOURCES.md
A14: CL-FUE-0013 | B14: Ticketplus · Región Metropolitana | C14: Ticketplus · Región Metropolitana | D14: Fuente configurada en el prototipo | E14: Según fuente | F14: Región Metropolitana de Santiago | H14: Multidisciplinario | I14: Conector del prototipo | J14: https://ticketplus.cl/states/region-metropolitana | K14: https://ticketplus.cl/states/region-metropolitana | L14: Reemplazada por cobertura nacional | M14: No | N14: Alta | O14: generic | P14: 46270.667 | Q14: Configuración histórica sustituida por Ticketplus · Chile. Se conserva como antecedente, pero no cuenta como una segunda integración ni como otra fuente elegible. | R14: Referencia sin agenda | S14: 87 | T14: alta | U14: 200 | V14: Permite | W14: https://ticketplus.cl/states/region-metropolitana | X14: 46279.625 | Y14: No se ejecuta ni se considera integración operativa. | Z14: 0 | AA14: Reemplazada | AB14: https://github.com/sunsitox/sunsitox-Scraper_de_eventos_culturales/blob/main/sources/ticketplus-rm.json
A15: CL-FUE-0014 | B15: Agenda Cultural UOH | C15: Universidad de O'Higgins | D15: Fuente configurada en el prototipo | E15: Según fuente | F15: Región del Libertador General Bernardo O'Higgins | G15: Rancagua | H15: Multidisciplinario | I15: Conector del prototipo | J15: https://www.uoh.cl/extension/agenda/ | K15: https://www.uoh.cl/extension/agenda/ | L15: Integrada configurada | M15: Sí | N15: Alta | O15: wordpress_rest | P15: 46326 | Q15: Revisión de integración 31-10-2026: configuración habilitada; 13 registros publicados no suprimidos en Supabase. Con aporte publicado. Los puntajes y la auditoría técnica anteriores no se recalcularon. Antecedente: Ejecución reciente: conector funcional. | R15: Aprobada técnicamente | S15: 99 | T15: alta | U15: 200 | V15: Permite | W15: https://www.uoh.cl/extension/agenda | X15: 46279.625 | Y15: Operativa: API WordPress y validación de URLs activas. | Z15: 13 | AA15: Con aporte publicado | AB15: https://github.com/sunsitox/sunsitox-Scraper_de_eventos_culturales/actions/runs/41029844675
A16: CL-FUE-0015 | B16: Valpo Cultura | C16: Dirección de Desarrollo Cultural · Municipalidad de Valparaíso | D16: Fuente configurada en el prototipo | E16: Según fuente | F16: Región de Valparaíso | G16: Valparaíso | H16: Multidisciplinario | I16: Conector del prototipo | J16: https://valpocultura.cl/agenda-cultural/ | K16: https://valpocultura.cl/agenda-cultural/ | L16: Integrada configurada | M16: Sí | N16: Alta | O16: tribe_events_api | P16: 46326 | Q16: Revisión de integración 31-10-2026: configuración habilitada; 2 registros publicados no suprimidos en Supabase. Con aporte publicado. Los puntajes y la auditoría técnica anteriores no se recalcularon. Antecedente: Ejecución reciente: conector funcional. | R16: Aprobada técnicamente | S16: 100 | T16: alta | U16: 200 | V16: Permite | W16: https://valpocultura.cl/agenda-cultural/ | X16: 46279.625 | Y16: Operativa: API de calendario funcional. | Z16: 2 | AA16: Con aporte publicado | AB16: https://github.com/sunsitox/sunsitox-Scraper_de_eventos_culturales/actions/runs/41029844675
A17: CL-FUE-0016 | B17: Día de los Patrimonios | C17: Ministerio de las Culturas, las Artes y el Patrimonio | D17: Programa nacional | E17: Nacional | F17: Todas | H17: Patrimonio; Museos; Artes | I17: Agenda web | J17: https://www.diadelospatrimonios.cl/ | K17: https://www.diadelospatrimonios.cl/ | L17: Candidata verificada | M17: Sí | N17: Alta | O17: API/HTML | P17: 46270.667 | Q17: Fuente digital recurrente; validar términos, paginación y estabilidad antes de integrarla. | R17: Revisión manual | S17: 53 | T17: media | U17: 200 | V17: Permite | W17: https://www.diadelpatrimonio.cl/ | X17: 46271.058 | Y17: sin términos de agenda | 0 objetos Event JSON-LD | 0 señales
A18: CL-FUE-0017 | B18: Museos de Chile | C18: Servicio Nacional del Patrimonio Cultural | D18: Directorio/agenda nacional | E18: Nacional | F18: Todas | H18: Museos; Patrimonio; Artes visuales | I18: Portal web | J18: https://www.museoschile.gob.cl/ | K18: https://www.museoschile.gob.cl/ | L18: Candidata verificada | M18: Sí | N18: Alta | O18: HTML | P18: 46270.667 | Q18: Fuente digital recurrente; validar términos, paginación y estabilidad antes de integrarla. | R18: Aprobada técnicamente | S18: 77 | T18: media | U18: 200 | V18: Permite | W18: https://www.museoschile.gob.cl/ | X18: 46271.058 | Y18: 0 objetos Event JSON-LD | 0 enlaces | /
A19: CL-FUE-0018 | B19: Bibliotecas Públicas | C19: Servicio Nacional del Patrimonio Cultural | D19: Red nacional | E19: Nacional | F19: Todas | H19: Literatura; Libro y lectura; Patrimonio | I19: Portal web | J19: https://www.bibliotecaspublicas.gob.cl/ | K19: https://www.bibliotecaspublicas.gob.cl/ | L19: Candidata verificada | M19: Sí | N19: Media | O19: HTML/RSS | P19: 46270.667 | Q19: Fuente digital recurrente; validar términos, paginación y estabilidad antes de integrarla. | R19: Revisión manual | S19: 76 | T19: media | U19: 200 | V19: Permite | W19: https://www.bibliotecaspublicas.gob.cl/ | X19: 46271.058 | Y19: programa | 0 objetos Event JSON-LD | 0 enlaces
A20: CL-FUE-0019 | B20: Patrimonio Cultural | C20: Servicio Nacional del Patrimonio Cultural | D20: Portal institucional | E20: Nacional | F20: Todas | H20: Patrimonio; Archivos; Bibliotecas; Museos | I20: Noticias/agenda | J20: https://www.patrimoniocultural.gob.cl/ | K20: https://www.patrimoniocultural.gob.cl/ | L20: Candidata verificada | M20: Sí | N20: Media | O20: HTML | P20: 46270.667 | Q20: Fuente digital recurrente; validar términos, paginación y estabilidad antes de integrarla. | R20: Aprobada técnicamente | S20: 92 | T20: alta | U20: 200 | V20: Permite | W20: https://www.patrimoniocultural.gob.cl/ | X20: 46271.058 | Y20: 0 objetos Event JSON-LD | /
A21: CL-FUE-0020 | B21: Red Cultura | C21: Ministerio de las Culturas, las Artes y el Patrimonio | D21: Programa/red nacional | E21: Nacional | F21: Todas | H21: Gestión cultural; Participación; Cultura comunitaria | I21: Portal web | J21: https://www.cultura.gob.cl/redcultura/ | K21: https://www.cultura.gob.cl/redcultura/ | L21: Candidata verificada | M21: Sí | N21: Baja | O21: HTML | P21: 46270.667 | Q21: Fuente digital recurrente; validar términos, paginación y estabilidad antes de integrarla. | R21: Revisión manual | S21: 74 | T21: media | U21: 200 | V21: Permite | W21: https://www.cultura.gob.cl/redcultura/ | X21: 46271.058 | Y21: programa | 0 objetos Event JSON-LD | 0 enlaces
A22: CL-FUE-0021 | B22: CECREA | C22: Ministerio de las Culturas, las Artes y el Patrimonio | D22: Red de centros | E22: Nacional | F22: Todas | H22: Infancias; Artes; Ciencia; Tecnología | I22: Cartelera por centro | J22: https://cecrea.cl/ | K22: https://cecrea.cl/ | L22: Candidata verificada | M22: Sí | N22: Media | O22: HTML | P22: 46270.667 | Q22: Fuente digital recurrente; validar términos, paginación y estabilidad antes de integrarla. | R22: Revisión manual | S22: 28 | T22: media | V22: Sin dato | X22: 46271.058 | Y22: error_tls: HTTPSConnectionPool(host='cecrea.cl', port=443): Max retries exceeded with url: / (Caused by SSLError(SSLError(1, '[SSL: TLSV1_UNRECOGNIZED_NAME] tlsv1 unrecognized name (_ssl.c:1082)'))) | sin Content-Type | sin términos de agenda
A23: CL-FUE-0022 | B23: Red Salas de Teatro | C23: Asociación Gremial Red de Salas de Teatro | D23: Red sectorial | E23: Nacional | F23: Varias | H23: Teatro; Danza; Circo | I23: Cartelera web | J23: https://redsalasdeteatro.cl/ | K23: https://redsalasdeteatro.cl/ | L23: Candidata verificada | M23: Sí | N23: Alta | O23: HTML | P23: 46270.667 | Q23: Fuente digital recurrente; validar términos, paginación y estabilidad antes de integrarla. | R23: Aprobada técnicamente | S23: 87 | T23: alta | U23: 200 | V23: Permite | W23: https://redsalasdeteatro.cl/ | X23: 46271.058 | Y23: 0 objetos Event JSON-LD | /
A24: CL-FUE-0023 | B24: Red Salas de Cine | C24: Red Salas Independientes de Cine de Chile | D24: Red sectorial | E24: Nacional | F24: Varias | H24: Cine; Audiovisual | I24: Carteleras enlazadas | J24: https://www.redsalasdecine.cl/ | K24: https://www.redsalasdecine.cl/salas-de-la-red/ | L24: Candidata verificada | M24: Sí | N24: Alta | O24: HTML | P24: 46270.667 | Q24: Fuente digital recurrente; validar términos, paginación y estabilidad antes de integrarla. | R24: Aprobada técnicamente | S24: 71 | T24: media | U24: 200 | V24: Permite | W24: https://www.redsalasdecine.cl/ | X24: 46271.058 | Y24: actividades | 0 objetos Event JSON-LD | 0 señales
A25: CL-FUE-0024 | B25: CineChile · Festivales | C25: Enciclopedia del Cine Chileno | D25: Directorio sectorial | E25: Nacional | F25: Varias | H25: Cine; Audiovisual; Festivales | I25: Directorio web | J25: https://cinechile.cl/festivales/ | K25: https://cinechile.cl/festivales/ | L25: Candidata verificada | M25: Sí | N25: Media | O25: HTML | P25: 46270.667 | Q25: Fuente digital recurrente; validar términos, paginación y estabilidad antes de integrarla. | R25: Aprobada técnicamente | S25: 92 | T25: alta | U25: 200 | V25: Permite | W25: https://cinechile.cl/festivales/ | X25: 46271.058 | Y25: programacion | 0 objetos Event JSON-LD
A26: CL-FUE-0025 | B26: MIC Chile | C26: Ministerio de las Culturas, las Artes y el Patrimonio | D26: Mercado/encuentro | E26: Nacional | F26: Varias | H26: Música; Industrias creativas | I26: Programación web | J26: https://micchile.cultura.gob.cl/ | K26: https://micchile.cultura.gob.cl/ | L26: Candidata verificada | M26: Sí | N26: Media | O26: HTML | P26: 46270.667 | Q26: Fuente digital recurrente; validar términos, paginación y estabilidad antes de integrarla. | R26: Aprobada técnicamente | S26: 85 | T26: alta | U26: 200 | V26: Sin dato | W26: https://micchile.cultura.gob.cl/ | X26: 46271.058 | Y26: 0 objetos Event JSON-LD | 1 enlaces | /
A27: CL-FUE-0026 | B27: PuntoTicket · Chile | C27: PuntoTicket | D27: Tiquetera | E27: Nacional | F27: Todas | H27: Música; Teatro; Humor; Festivales | I27: Cartelera | J27: https://www.puntoticket.com/ | K27: https://www.puntoticket.com/ | L27: Integrada configurada | M27: Sí | N27: Alta | O27: puntoticket_json | P27: 46326 | Q27: Revisión de integración 31-10-2026: configuración habilitada; 215 registros publicados no suprimidos en Supabase. Con aporte publicado. Los puntajes y la auditoría técnica anteriores no se recalcularon. Antecedente: Fuente digital recurrente; validar términos, paginación y estabilidad antes de integrarla. | R27: Aprobada técnicamente | S27: 90 | T27: alta | U27: 200 | V27: Permite | W27: https://www.puntoticket.com/ | X27: 46271.058 | Y27: 0 objetos Event JSON-LD | / | Z27: 215 | AA27: Con aporte publicado | AB27: https://github.com/sunsitox/sunsitox-Scraper_de_eventos_culturales/actions/runs/41029844675
A28: CL-FUE-0027 | B28: Ticketmaster Chile | C28: Ticketmaster Chile | D28: Tiquetera | E28: Nacional | F28: Todas | H28: Música; Teatro; Festivales | I28: Cartelera | J28: https://www.ticketmaster.cl/ | K28: https://www.ticketmaster.cl/ | L28: Candidata verificada | M28: Sí | N28: Alta | O28: API/HTML | P28: 46270.667 | Q28: Fuente digital recurrente; validar términos, paginación y estabilidad antes de integrarla. | R28: Aprobada técnicamente | S28: 88 | T28: alta | U28: 200 | V28: Permite | W28: https://www.ticketmaster.cl/ | X28: 46271.058 | Y28: 0 objetos Event JSON-LD | 1 enlaces | /
A29: CL-FUE-0028 | B29: Ticketplus · Chile | C29: Ticketplus | D29: Tiquetera | E29: Nacional | F29: Chile | H29: Música; Teatro; Cultura; Festivales | I29: Carteleras regionales | J29: https://ticketplus.cl/states/region-metropolitana | K29: https://ticketplus.cl/ | L29: Integrada configurada | M29: Sí | N29: Alta | O29: ticketplus_chile | P29: 46326 | Q29: Revisión de integración 31-10-2026: configuración habilitada; 465 registros publicados no suprimidos en Supabase. Con aporte publicado. Los puntajes y la auditoría técnica anteriores no se recalcularon. Antecedente: Conector nacional activo: descubre las 16 carteleras regionales y aísla los fallos por región. | R29: Aprobada técnicamente | S29: 80 | T29: alta | U29: 200 | V29: Permite | W29: https://ticketplus.cl/ | X29: 46285.625 | Y29: Operativa con cobertura nacional, extracción incremental y filtro cultural global. | Z29: 465 | AA29: Con aporte publicado | AB29: https://github.com/sunsitox/sunsitox-Scraper_de_eventos_culturales/actions/runs/41029844675
A30: CL-FUE-0029 | B30: Passline · Chile | C30: Passline | D30: Tiquetera | E30: Nacional | F30: Todas | H30: Música; Teatro; Festivales; Ferias | I30: Cartelera | J30: https://home.passline.com/home | K30: https://www.passline.com/ | L30: Integrada configurada | M30: Sí | N30: Alta | O30: passline_json | P30: 46326 | Q30: Revisión de integración 31-10-2026: configuración habilitada; 1355 registros publicados no suprimidos en Supabase. Con aporte publicado. Los puntajes y la auditoría técnica anteriores no se recalcularon. Antecedente: Fuente digital recurrente; validar términos, paginación y estabilidad antes de integrarla. | R30: Revisión manual | S30: 50 | T30: media | U30: 200 | V30: Permite | W30: https://home.passline.com | X30: 46271.058 | Y30: 0 objetos Event JSON-LD | 0 señales | 1 enlaces | Z30: 1355 | AA30: Con aporte publicado | AB30: https://github.com/sunsitox/sunsitox-Scraper_de_eventos_culturales/actions/runs/41029844675
A31: CL-FUE-0030 | B31: Eventrid | C31: Eventrid | D31: Tiquetera | E31: Nacional | F31: Todas | H31: Música; Cultura; Congresos; Ferias | I31: Cartelera | J31: https://www.eventrid.cl/ | K31: https://www.eventrid.cl/ | L31: Candidata verificada | M31: Sí | N31: Media | O31: API/HTML | P31: 46270.667 | Q31: Fuente digital recurrente; validar términos, paginación y estabilidad antes de integrarla. | R31: Revisión manual | S31: 56 | T31: media | U31: 200 | V31: Permite | W31: https://www.eventrid.cl/ | X31: 46271.058 | Y31: eventos | 0 objetos Event JSON-LD | 0 señales
A32: CL-FUE-0031 | B32: Welcu | C32: Welcu | D32: Plataforma de eventos | E32: Nacional | F32: Todas | H32: Cultura; Talleres; Ferias; Conferencias | I32: Buscador | J32: https://welcu.com/ | K32: https://welcu.com/ | L32: Candidata verificada | M32: Sí | N32: Media | O32: HTML | P32: 46270.667 | Q32: Fuente digital recurrente; validar términos, paginación y estabilidad antes de integrarla. | R32: Aprobada técnicamente | S32: 100 | T32: alta | U32: 200 | V32: Permite | W32: https://welcu.com/es | X32: 46271.058 | Y32: 0 objetos Event JSON-LD | /es
A33: CL-FUE-0032 | B33: PortalTickets | C33: PortalTickets | D33: Tiquetera | E33: Nacional | F33: Todas | H33: Música; Teatro; Festivales | I33: Cartelera | J33: https://www.portaltickets.cl/ | K33: https://www.portaltickets.cl/ | L33: Candidata verificada | M33: Sí | N33: Media | O33: HTML | P33: 46270.667 | Q33: Fuente digital recurrente; validar términos, paginación y estabilidad antes de integrarla. | R33: Aprobada técnicamente | S33: 94 | T33: alta | U33: 200 | V33: Permite | W33: https://www.portaldisc.com/portaltickets | X33: 46271.058 | Y33: 0 objetos Event JSON-LD | /portaltickets
A34: CL-FUE-0033 | B34: EcoPass | C34: EcoPass | D34: Tiquetera | E34: Nacional | F34: Todas | H34: Música; Cultura; Ferias | I34: Cartelera | J34: https://www.ecopass.cl/ | K34: https://www.ecopass.cl/ | L34: Candidata verificada | M34: Sí | N34: Media | O34: HTML | P34: 46270.667 | Q34: Fuente digital recurrente; validar términos, paginación y estabilidad antes de integrarla. | R34: Revisión manual | S34: 33 | T34: media | U34: 403 | V34: Permite | W34: https://www.ecopass.cl/ | X34: 46271.058 | Y34: http_403 | sin términos de agenda | 0 objetos Event JSON-LD
A35: CL-FUE-0034 | B35: Fundación Teatro a Mil | C35: Fundación Teatro a Mil | D35: Festival/productora | E35: Nacional | F35: Varias | H35: Teatro; Danza; Circo; Artes escénicas | I35: Cartelera | J35: https://teatroamil.cl/ | K35: https://teatroamil.cl/ | L35: Candidata verificada | M35: Sí | N35: Alta | O35: API/HTML | P35: 46270.667 | Q35: Fuente digital recurrente; validar términos, paginación y estabilidad antes de integrarla. | R35: Revisión manual | S35: 72 | T35: media | U35: 200 | V35: Permite | W35: https://teatroamil.cl/ | X35: 46271.058 | Y35: 0 objetos Event JSON-LD | 0 señales | 1 enlaces
A36: CL-FUE-0035 | B36: Cultura Arica | C36: Municipalidad de Arica | D36: Agenda municipal | E36: Regional/comunal | F36: Región de Arica y Parinacota | G36: Arica | H36: Multidisciplinario; Patrimonio | I36: Portal municipal | J36: https://www.muniarica.cl/ | K36: https://www.muniarica.cl/ | L36: Candidata verificada | M36: Sí | N36: Media | O36: HTML | P36: 46270.667 | Q36: Fuente digital recurrente; validar términos, paginación y estabilidad antes de integrarla. | R36: Aprobada técnicamente | S36: 74 | T36: media | U36: 200 | V36: Permite | W36: https://www.muniarica.cl/ | X36: 46271.058 | Y36: 0 objetos Event JSON-LD | /
A37: CL-FUE-0036 | B37: Festival Internacional de Cine Arica Nativa | C37: Fundación Altiplano | D37: Festival | E37: Regional | F37: Región de Arica y Parinacota | G37: Arica | H37: Cine; Patrimonio; Pueblos originarios | I37: Programación | J37: https://www.aricanativa.cl/ | K37: https://www.aricanativa.cl/ | L37: Candidata verificada | M37: Sí | N37: Media | O37: HTML | P37: 46270.667 | Q37: Fuente digital recurrente; validar términos, paginación y estabilidad antes de integrarla. | R37: Revisión manual | S37: 74 | T37: media | U37: 200 | V37: Permite | W37: https://www.aricanativa.cl/ | X37: 46271.058 | Y37: proximamente | 0 objetos Event JSON-LD | 0 enlaces
A38: CL-FUE-0037 | B38: Iquique Cultural | C38: Corporación Municipal de Desarrollo Social de Iquique | D38: Agenda municipal | E38: Regional/comunal | F38: Región de Tarapacá | G38: Iquique | H38: Multidisciplinario | I38: Portal institucional | J38: https://www.municipioiquique.cl/ | K38: https://www.municipioiquique.cl/ | L38: Candidata verificada | M38: Sí | N38: Baja | O38: HTML | P38: 46270.667 | Q38: Fuente digital recurrente; validar términos, paginación y estabilidad antes de integrarla. | R38: Revisión manual | S38: 66 | T38: media | U38: 200 | V38: Permite | W38: https://www.municipioiquique.cl/ | X38: 46271.058 | Y38: cultural | 0 objetos Event JSON-LD | /
A39: CL-FUE-0038 | B39: Teatro Municipal de Iquique | C39: Municipalidad de Iquique | D39: Teatro municipal | E39: Regional | F39: Región de Tarapacá | G39: Iquique | H39: Teatro; Música; Danza | I39: Cartelera | J39: https://www.teatromunicipaliquique.cl/ | K39: https://www.teatromunicipaliquique.cl/ | L39: Candidata verificada | M39: Sí | N39: Alta | O39: HTML | P39: 46270.667 | Q39: Fuente digital recurrente; validar términos, paginación y estabilidad antes de integrarla. | R39: Revisión manual | S39: 32 | T39: media | V39: Sin dato | X39: 46271.058 | Y39: error_red: HTTPSConnectionPool(host='www.teatromunicipaliquique.cl', port=443): Max retries exceeded with url: / (Caused by NameResolutionError("HTTPSConnection(host='www.teatromunicipaliquique.cl', port=443): Failed to resolve 'www.teatromunicipaliqu | sin Content-Type | sin términos de agenda
A40: CL-FUE-0039 | B40: Cultura Antofagasta | C40: Corporación Cultural de Antofagasta | D40: Agenda cultural | E40: Regional/comunal | F40: Región de Antofagasta | G40: Antofagasta | H40: Música; Teatro; Danza; Artes | I40: Portal institucional | J40: https://culturaantofagasta.cl/ | K40: https://culturaantofagasta.cl/ | L40: Candidata verificada | M40: Sí | N40: Alta | O40: HTML | P40: 46270.667 | Q40: Fuente digital recurrente; validar términos, paginación y estabilidad antes de integrarla. | R40: Aprobada técnicamente | S40: 83 | T40: alta | U40: 200 | V40: Permite | W40: https://culturaantofagasta.cl/ | X40: 46271.058 | Y40: 0 objetos Event JSON-LD | 0 señales | /
...

Sheet Criterios
A1: Criterios, alcance y trazabilidad
A2: Metodología para mantener el inventario y evitar que el porcentaje de avance sea engañoso.
A4: Concepto | B4: Definición / regla
A5: Fuente digital evaluable | B5: Sitio, API, calendario, cartelera, tiquetera o agenda recurrente con una URL pública que puede comprobarse.
A6: Aprobada técnicamente | B6: Cumple acceso, contenido compatible, relevancia cultural, cobertura chilena y señales suficientes de una agenda recurrente. Puede avanzar a diseño de conector.
A7: Revisión manual | B7: La fuente puede ser válida, pero depende de JavaScript, presenta bloqueo temporal, agotó el tiempo o no mostró evidencia suficiente para una decisión automática.
A8: No aprobada | B8: No debe incorporarse al scraping automático en su estado actual. Incluye URLs muertas, contenido no cultural, páginas estacionadas o prohibición expresa de robots.txt.
A9: Referencia sin agenda | B9: Espacio cultural sin URL de eventos identificada. Se conserva como pista territorial y no se cuenta como fuente digital evaluada.
A10: Estado de integración actual | B10: Estado actual de integración según los JSON del scraper. Una configuración habilitada no demuestra por sí sola una extracción completa o eventos vigentes.
A11: Porcentaje aprobado | B11: Aprobación técnica registrada / fuentes digitales elegibles. Las referencias territoriales, retiradas y configuraciones reemplazadas no forman parte del denominador.
A12: Ámbito cultural incluido | B12: Música, teatro, danza, circo, cine, artes visuales, literatura, patrimonio, museos, artesanía, diseño, cultura comunitaria, pueblos originarios, vendimias, gastronomía patrimonial, ferias y exposiciones culturales.
A13: Fecha de revisión | B13: Inventario e integración revisados: 31-10-2026. La columna Auditada el conserva la fecha de la evaluación técnica original; no se ejecutó otra auditoría completa.
A14: Alcance legal | B14: La aprobación es técnica. robots.txt y accesibilidad no constituyen por sí solos una licencia de reutilización; los términos de uso deben comprobarse antes de la operación permanente.
A15: Limitación | B15: Las páginas cambian y algunas cargan datos solo en el navegador. Las fuentes en revisión manual requieren una inspección adicional antes de aprobarse o descartarse.
A16: Porcentaje de integración | B16: El avance de integración es configuradas y habilitadas / digitales elegibles. El aporte operativo es fuentes con registros publicados / habilitadas en el mes. No confundir ambos porcentajes.
A18: Referencia principal | B18: Uso en el inventario | C18: URL
A19: Chile Cultura | B19: Agenda nacional oficial | C19: https://chilecultura.gob.cl/
A20: ChileAtiende · Chile Cultura | B20: Respaldo institucional y cobertura nacional | C20: https://www.chileatiende.gob.cl/fichas/77453-Chile-cultura
A21: Directorio Nacional de Espacios Culturales 2025 | B21: Base territorial oficial de espacios culturales | C21: https://ciudadania.cultura.gob.cl/directorio_rc_1/
A22: PDF del Directorio Nacional | B22: Fichas OCR incluidas como referencias territoriales | C22: https://ciudadania.cultura.gob.cl/wp-content/uploads/2025/12/Directorio_Espacios-Culturales-2025_RC.pdf
A23: Enoturismo Chile | B23: Agenda y calendario de vendimias | C23: https://www.enoturismochile.cl/descargas/
A24: Red Salas de Cine | B24: Red de espacios de exhibición independiente | C24: https://www.redsalasdecine.cl/salas-de-la-red/
A25: Red Salas de Teatro | B25: Red sectorial de salas y carteleras | C25: https://redsalasdeteatro.cl/
A26: CineChile · Festivales | B26: Directorio de festivales audiovisuales | C26: https://cinechile.cl/festivales/
A28: Publicados al corte | B28: Conteo de registros published con is_suppressed=false consultados en Supabase el 31-10-2026. No certifica vigencia horaria ni pertinencia de todos los casos en revisión.
A29: Fuentes estacionales | B29: FondasChile conserva su integración, pero solo se ejecuta en septiembre. En octubre se excluye del denominador de habilitadas del mes.
A30: Puntaje técnico | B30: Se conserva el puntaje histórico existente. Las incorporaciones sin auditoría comparable no reciben un puntaje inventado ni una aprobación automática.
A31: Retiradas y reemplazadas | B31: Rancagua Cultura, Teatro del Lago y Teatro Oriente están retiradas. Ticketplus Región Metropolitana es un antecedente reemplazado por Ticketplus Chile, no otra integración.
A32: Última ingesta exitosa | B32: El resumen conserva el conteo y la fecha de scrape_runs. Su duración corresponde a la publicación registrada, no al tiempo total del workflow.
